2021-11-08T10:09:39.958817+00:00 app[worker.1]: pymongo.errors.OperationFailure: bad auth : Authentication failed., full error: {'ok': 0, 'errmsg': 'bad auth : Authentication failed.', 'code': 8000, 'codeName': 'AtlasError'}
2021-11-08T10:10:28.982939+00:00 app[api]: Release v5 created by user tomj14666@gmail.com
2021-11-08T10:10:28.982939+00:00 app[api]: Set DATABASE_1 config vars by user tomj14666@gmail.com
2021-11-08T10:10:29.607799+00:00 heroku[worker.1]: Restarting
2021-11-08T10:10:29.630711+00:00 heroku[worker.1]: State changed from up to starting
2021-11-08T10:10:30.537015+00:00 heroku[worker.1]: Stopping all processes with SIGTERM
2021-11-08T10:10:31.438003+00:00 app[worker.1]: Bot stopped. Bye.
2021-11-08T10:10:31.830717+00:00 heroku[worker.1]: Process exited with status 0
2021-11-08T10:10:32.856723+00:00 heroku[worker.1]: Starting process with command `python3 mt_botz.py`
2021-11-08T10:10:34.271753+00:00 heroku[worker.1]: State changed from starting to up
2021-11-08T10:10:36.966081+00:00 app[worker.1]: Pyrogram v1.2.9, Copyright (C) 2017-2021 Dan <https://github.com/delivrance>
2021-11-08T10:10:36.966564+00:00 app[worker.1]: Licensed under the terms of the GNU Lesser General Public License v3 or later (LGPLv3+)
2021-11-08T10:10:36.966565+00:00 app[worker.1]: 
2021-11-08T10:10:41.923013+00:00 app[worker.1]: ᴛᴀɴᴊɪʀᴏ ᴋᴀᴍᴀᴅᴏ ⚡ with for Pyrogram v1.2.9 (Layer 128) started on Movie_Roster_bot.
2021-11-08T10:10:51.259044+00:00 app[worker.1]: 10:10:51 AM - 230 - pyrogram.dispatcher - dispatcher - ERROR - bad auth : Authentication failed., full error: {'ok': 0, 'errmsg': 'bad auth : Authentication failed.', 'code': 8000, 'codeName': 'AtlasError'}
2021-11-08T10:10:51.259053+00:00 app[worker.1]: Traceback (most recent call last):
2021-11-08T10:10:51.259054+00:00 app[worker.1]:   File "/app/.heroku/python/lib/python3.8/site-packages/pymongo/pool.py", line 1278, in _get_socket
2021-11-08T10:10:51.259054+00:00 app[worker.1]:     sock_info = self.sockets.popleft()
2021-11-08T10:10:51.259054+00:00 app[worker.1]: IndexError: pop from an empty deque
2021-11-08T10:10:51.259054+00:00 app[worker.1]: 
2021-11-08T10:10:51.259055+00:00 app[worker.1]: During handling of the above exception, another exception occurred:
2021-11-08T10:10:51.259055+00:00 app[worker.1]: 
2021-11-08T10:10:51.259056+00:00 app[worker.1]: Traceback (most recent call last):
2021-11-08T10:10:51.259056+00:00 app[worker.1]:   File "/app/.heroku/python/lib/python3.8/site-packages/pyrogram/dispatcher.py", line 217, in handler_worker
2021-11-08T10:10:51.259056+00:00 app[worker.1]:     await handler.callback(self.client, *args)
2021-11-08T10:10:51.259056+00:00 app[worker.1]:   File "/app/.heroku/python/lib/python3.8/site-packages/pyromod/listen/listen.py", line 93, in resolve_listener
2021-11-08T10:10:51.259057+00:00 app[worker.1]:     await self.user_callback(client, message, *args)
2021-11-08T10:10:51.259057+00:00 app[worker.1]:   File "/app/LuciferMoringstar_Robot/Commands.py", line 22, in start
2021-11-08T10:10:51.259057+00:00 app[worker.1]:     if not await db.is_user_exist(chat_id):
2021-11-08T10:10:51.259057+00:00 app[worker.1]:   File "/app/Database/Database.py", line 31, in is_user_exist
2021-11-08T10:10:51.259058+00:00 app[worker.1]:     user = await self.col.find_one({"id": int(id)})
2021-11-08T10:10:51.259058+00:00 app[worker.1]:   File "/app/.heroku/python/lib/python3.8/concurrent/futures/thread.py", line 57, in run
2021-11-08T10:10:51.259058+00:00 app[worker.1]:     result = self.fn(*self.args, **self.kwargs)
2021-11-08T10:10:51.259059+00:00 app[worker.1]:   File "/app/.heroku/python/lib/python3.8/site-packages/pymongo/collection.py", line 1319, in find_one
2021-11-08T10:10:51.259059+00:00 app[worker.1]:     for result in cursor.limit(-1):
2021-11-08T10:10:51.259059+00:00 app[worker.1]:   File "/app/.heroku/python/lib/python3.8/site-packages/pymongo/cursor.py", line 1207, in next
2021-11-08T10:10:51.259059+00:00 app[worker.1]:     if len(self.__data) or self._refresh():
2021-11-08T10:10:51.259059+00:00 app[worker.1]:   File "/app/.heroku/python/lib/python3.8/site-packages/pymongo/cursor.py", line 1124, in _refresh
2021-11-08T10:10:51.259060+00:00 app[worker.1]:     self.__send_message(q)
2021-11-08T10:10:51.259060+00:00 app[worker.1]:   File "/app/.heroku/python/lib/python3.8/site-packages/pymongo/cursor.py", line 999, in __send_message
2021-11-08T10:10:51.259060+00:00 app[worker.1]:     response = client._run_operation_with_response(
2021-11-08T10:10:51.259061+00:00 app[worker.1]:   File "/app/.heroku/python/lib/python3.8/site-packages/pymongo/mongo_client.py", line 1368, in _run_operation_with_response
2021-11-08T10:10:51.259061+00:00 app[worker.1]:     return self._retryable_read(
2021-11-08T10:10:51.259061+00:00 app[worker.1]:   File "/app/.heroku/python/lib/python3.8/site-packages/pymongo/mongo_client.py", line 1464, in _retryable_read
2021-11-08T10:10:51.259062+00:00 app[worker.1]:     with self._slaveok_for_server(read_pref, server, session,
2021-11-08T10:10:51.259062+00:00 app[worker.1]:   File "/app/.heroku/python/lib/python3.8/contextlib.py", line 113, in __enter__
2021-11-08T10:10:51.259062+00:00 app[worker.1]:     return next(self.gen)
2021-11-08T10:10:51.259062+00:00 app[worker.1]:   File "/app/.heroku/python/lib/python3.8/site-packages/pymongo/mongo_client.py", line 1309, in _slaveok_for_server
2021-11-08T10:10:51.259063+00:00 app[worker.1]:     with self._get_socket(server, session, exhaust=exhaust) as sock_info:
2021-11-08T10:10:51.259063+00:00 app[worker.1]:   File "/app/.heroku/python/lib/python3.8/contextlib.py", line 113, in __enter__
2021-11-08T10:10:51.259063+00:00 app[worker.1]:     return next(self.gen)
2021-11-08T10:10:51.259063+00:00 app[worker.1]:   File "/app/.heroku/python/lib/python3.8/site-packages/pymongo/mongo_client.py", line 1246, in _get_socket
2021-11-08T10:10:51.259063+00:00 app[worker.1]:     with server.get_socket(
2021-11-08T10:10:51.259064+00:00 app[worker.1]:   File "/app/.heroku/python/lib/python3.8/contextlib.py", line 113, in __enter__
2021-11-08T10:10:51.259064+00:00 app[worker.1]:     return next(self.gen)
2021-11-08T10:10:51.259064+00:00 app[worker.1]:   File "/app/.heroku/python/lib/python3.8/site-packages/pymongo/pool.py", line 1231, in get_socket
2021-11-08T10:10:51.259064+00:00 app[worker.1]:     sock_info = self._get_socket(all_credentials)
2021-11-08T10:10:51.259093+00:00 app[worker.1]:   File "/app/.heroku/python/lib/python3.8/site-packages/pymongo/pool.py", line 1281, in _get_socket
2021-11-08T10:10:51.259093+00:00 app[worker.1]:     sock_info = self.connect(all_credentials)
2021-11-08T10:10:51.259094+00:00 app[worker.1]:   File "/app/.heroku/python/lib/python3.8/site-packages/pymongo/pool.py", line 1197, in connect
2021-11-08T10:10:51.259094+00:00 app[worker.1]:     sock_info.check_auth(all_credentials)
2021-11-08T10:10:51.259094+00:00 app[worker.1]:   File "/app/.heroku/python/lib/python3.8/site-packages/pymongo/pool.py", line 793, in check_auth
2021-11-08T10:10:51.259094+00:00 app[worker.1]:     self.authenticate(credentials)
2021-11-08T10:10:51.259095+00:00 app[worker.1]:   File "/app/.heroku/python/lib/python3.8/site-packages/pymongo/pool.py", line 810, in authenticate
2021-11-08T10:10:51.259095+00:00 app[worker.1]:     auth.authenticate(credentials, self)
2021-11-08T10:10:51.259095+00:00 app[worker.1]:   File "/app/.heroku/python/lib/python3.8/site-packages/pymongo/auth.py", line 673, in authenticate
2021-11-08T10:10:51.259095+00:00 app[worker.1]:     auth_func(credentials, sock_info)
2021-11-08T10:10:51.259095+00:00 app[worker.1]:   File "/app/.heroku/python/lib/python3.8/site-packages/pymongo/auth.py", line 591, in _authenticate_default
2021-11-08T10:10:51.259095+00:00 app[worker.1]:     return _authenticate_scram(credentials, sock_info, 'SCRAM-SHA-1')
2021-11-08T10:10:51.259096+00:00 app[worker.1]:   File "/app/.heroku/python/lib/python3.8/site-packages/pymongo/auth.py", line 333, in _authenticate_scram
2021-11-08T10:10:51.259096+00:00 app[worker.1]:     res = sock_info.command(source, cmd)
2021-11-08T10:10:51.259096+00:00 app[worker.1]:   File "/app/.heroku/python/lib/python3.8/site-packages/pymongo/pool.py", line 683, in command
2021-11-08T10:10:51.259096+00:00 app[worker.1]:     return command(self, dbname, spec, slave_ok,
2021-11-08T10:10:51.259102+00:00 app[worker.1]:   File "/app/.heroku/python/lib/python3.8/site-packages/pymongo/network.py", line 159, in command
2021-11-08T10:10:51.259102+00:00 app[worker.1]:     helpers._check_command_response(
2021-11-08T10:10:51.259102+00:00 app[worker.1]:   File "/app/.heroku/python/lib/python3.8/site-packages/pymongo/helpers.py", line 164, in _check_command_response
2021-11-08T10:10:51.259103+00:00 app[worker.1]:     raise OperationFailure(errmsg, code, response, max_wire_version)
2021-11-08T10:10:51.259109+00:00 app[worker.1]: pymongo.errors.OperationFailure: bad auth : Authentication failed., full error: {'ok': 0, 'errmsg': 'bad auth : Authentication failed.', 'code': 8000, 'codeName': 'AtlasError'}